<mujoco model = "simple">
    <compiler inertiafromgeom = 'true' angle = 'degree'/>

    <default>
        <joint limited='true' damping='1' armature='0' />
        <geom contype='1' conaffinity='1' condim='1' rgba='0.8 0.6 .4 1'
        	margin="0.001" solref=".02 1" solimp=".8 .8 .01" material="geom"/>
        <motor ctrlrange='-.4 .4' ctrllimited='true'/>
    </default>

    <option timestep='0.002' iterations="50" solver="PGS">
        <flag energy="enable"/>
    </option>

    <visual>
        <map fogstart="3" fogend="5" force="0.1"/>
        <quality shadowsize="2048"/>
    </visual>

    <asset>
        <texture type="skybox" builtin="gradient" width="100" height="100" rgb1=".4 .6 .8"
            rgb2="0 0 0"/>
        <texture name="texgeom" type="cube" builtin="flat" mark="cross" width="127" height="1278"
            rgb1="0.8 0.6 0.4" rgb2="0.8 0.6 0.4" markrgb="1 1 1" random="0.01"/>
        <texture name="texplane" type="2d" builtin="checker" rgb1=".2 .3 .4" rgb2=".1 0.15 0.2"
            width="100" height="100"/>

        <material name='MatPlane' reflectance='0.5' texture="texplane" texrepeat="1 1" texuniform="true"/>
        <material name='geom' texture="texgeom" texuniform="true"/>
    </asset>

    <worldbody>
        <geom name = 'floor' pos = '0 0 0' size = '10 10 0.1' type = 'plane' material = 'Matplane' condim = '3'/>
        <body name = 'bodypart' pos = '0 0 2'>
            <geom name = 'thigh' type = 'capsule' fromto = '0 0 0 0 0.01 -0.34' size='0.09'/>
            <body name = 'shinBody' pos = '0 0.01 -0.403'>
                <joint name = 'knee' type = 'hinge' pos = '0 0 0.02' axis='0 -1 0' range = '-160 -2' stiffness ='1' armature='0.0060'/>
                <geom name = 'shin' type ='capsule' fromto ='0 0 0 0 0 -0.3' size = '0.09' />
            </body>
        </body>
    </worldbody>

    <actuator>
        <motor name = 'kneeMotor' gear = '400' joint = 'knee'/>
    </actuator>

</mujoco>